Workbook

Sheet Resumen
A1: Riopaila · impacto de la restricción presupuestal en el TCH
A2: Todas las cifras salen de las otras hojas (fórmulas). TCH = toneladas ÷ ha a cosechar del año. 2027: estado de labores a hoy; riego = escenario El Niño.
A4: Factor | B4: 2026 · Ha afectadas | C4: 2026 · Toneladas | D4: 2026 · TCH | E4: 2027 · Ha afectadas | F4: 2027 · Toneladas | G4: 2027 · TCH | H4: Hoja
A5: Menor renovación | B5: =Renovación!$D$75 -> 635.7 | C5: =Renovación!$H$75 -> 5788.3724 | D5: =C5/'Efectos y supuestos'!$B$6 -> 1.106093 | E5: =Renovación!$D$78 -> 605.69 | F5: =Renovación!$D$80 -> 6833.27 | G5: =F5/'Efectos y supuestos'!$B$7 -> 1.2670629 | H5: Renovación
A6: Corte a siembra | B6: ='Corte a siembra'!$B$51 -> 302.75 | C6: 0 | D6: =C6/'Efectos y supuestos'!$B$6 -> 0 | E6: ='Corte a siembra'!$B$109 -> 453.39 | F6: 0 | G6: =F6/'Efectos y supuestos'!$B$7 -> 0 | H6: Corte a siembra
A7: Fertilización | B7: =Fertilización!$C$232 -> 22.79 | C7: 0 | D7: =C7/'Efectos y supuestos'!$B$6 -> 0 | E7: =Fertilización!$C$235 -> 440.52 | F7: 0 | G7: =F7/'Efectos y supuestos'!$B$7 -> 0 | H7: Fertilización
A8: Roturación tardía | B8: =Roturación!$E$375 -> 284.66 | C8: =Roturación!$H$375 -> 1784.2709 | D8: =C8/'Efectos y supuestos'!$B$6 -> 0.34095413 | E8: =Roturación!$E$845 -> 906.97 | F8: =Roturación!$H$845 -> 5885.57 | G8: =F8/'Efectos y supuestos'!$B$7 -> 1.0913351 | H8: Roturación
A9: Control de malezas | B9: =Malezas!$E$324 -> 862.86 | C9: =Malezas!$H$324 -> 1941.0984 | D9: =C9/'Efectos y supuestos'!$B$6 -> 0.37092211 | E9: =Malezas!$E$794 -> 1447.08 | F9: =Malezas!$H$794 -> 1465.9912 | G9: =F9/'Efectos y supuestos'!$B$7 -> 0.27183223 | H9: Malezas
A10: Falta de riego | B10: ='Riego y lluvia'!$C$9 -> 2117.66 | C10: ='Riego y lluvia'!$F$9 -> 4764.3892 | D10: =C10/'Efectos y supuestos'!$B$6 -> 0.91042126 | E10: ='Riego y lluvia'!$C$21 -> 5393 | F10: ='Riego y lluvia'!$F$21 -> 8194.3217 | G10: =F10/'Efectos y supuestos'!$B$7 -> 1.5194366 | H10: Riego y lluvia
A11: Precipitaciones | B11: ='Riego y lluvia'!$C$12 -> 1874.52 | C11: ='Riego y lluvia'!$F$12 -> 1035.3799 | D11: =C11/'Efectos y supuestos'!$B$6 -> 0.19784948 | E11: ='Riego y lluvia'!$C$22 -> 1303.71 | F11: ='Riego y lluvia'!$F$22 -> -486.41689 | G11: =F11/'Efectos y supuestos'!$B$7 -> -0.09019412 | H11: Riego y lluvia
A12: Lucro cesante | B12: ='Lucro cesante'!$B$41 -> 332.23 | C12: ='Lucro cesante'!$G$41 -> 13663.032 | D12: =C12/'Efectos y supuestos'!$B$6 -> 2.610852 | E12: ='Lucro cesante'!$B$46 -> 20.77 | F12: ='Lucro cesante'!$G$46 -> 675.13893 | G12: =F12/'Efectos y supuestos'!$B$7 -> 0.12518801 | H12: Lucro cesante
A13: Total | C13: =SUM(C5:C12) -> 28976.543 | D13: =C13/'Efectos y supuestos'!$B$6 -> 5.5370919 | F13: =SUM(F5:F12) -> 22567.875 | G13: =F13/'Efectos y supuestos'!$B$7 -> 4.1846607
A15: Ha a cosechar | B15: ='Efectos y supuestos'!$B$6 -> 5233.17 | E15: ='Efectos y supuestos'!$B$7 -> 5393
A16: Negativo = a favor. Corte a siembra y fertilización: sin efecto medible (0 t). Los factores se midieron por separado y pueden traslaparse.

Sheet Efectos y supuestos
A1: Efectos medidos y supuestos (celdas azules = dato; se pueden cambiar y el libro se recalcula)
A2: Efectos medidos con cosechas de Riopaila, cada suerte frente a su propio promedio 2020-25, con efectos de año, mes, edad y corte.
A3: Concepto | B3: Valor | C3: Fuente / cómo se midió
A4: Ha cosechadas 2026 (ene-oct) | B4: 3215.66 | C4: ZQM / G&P a septiembre + app de Cosecha octubre
A5: Ha por cosechar 2026 (nov-dic) | B5: 2017.51 | C5: Maestro: próximo corte en 2026 sin cosecha registrada
A6: Ha a cosechar 2026 | B6: =B4+B5 -> 5233.17 | C6: Denominador del impacto en TCH 2026
A7: Ha a cosechar 2027 | B7: 5393 | C7: Presupuesto de cosecha 2027 (proyección)
A8: Roturación 1.ª labor TARDÍA (>30 días) | B8: -0.063 | C8: Control oficial de roturación; cosechas 2024-26, n=803; p<0,01; controla suelo húmedo (sin control −10,9 %)
A9: Malezas: por cada 30 días de atraso del 1.er control químico | B9: -0.0146 | C9: SimpleAgri; socas cosechadas 2024-26, n=1.011; p=0,007. Con la fecha real de aplicaciones (cosechas 2026, n=259): −2,3 % (p=0,11); se deja el menor
A10: Malezas: plazo del protocolo (días) | B10: 90 | C10: Pedido del usuario (22-oct): el primer control hasta 90 días cuenta como oportuno; se cuenta solo el atraso más allá
A11: Malezas: ciclo sin control químico | B11: -0.0524 | C11: −6,7 % frente a ≤60 días (p=0,001), menos lo que ya restaría un control a los 90 días (−1,46 %)
A12: Riego: déficit sin cubrir meses 0-4 (por 100 mm) | B12: 0.0070166177 | C12: Modelo de riego 2022-26 (arranque seco ayuda)
A13: Riego: déficit sin cubrir meses 4-8 (por 100 mm) | B13: -0.0045347778 | C13: Modelo de riego 2022-26
A14: Riego: déficit sin cubrir del mes 8 a la cosecha (por 100 mm) | B14: -0.012535365 | C14: Modelo de riego 2022-26; p<0,001
A15: Lluvia del arranque, meses 0-3 (por 100 mm) | B15: -0.012079619 | C15: Modelo de factores 2011-26 (más lluvia al arrancar = menos TCH)
A16: TCHM Riopaila 2024-25 (t/ha por mes) | B16: 9.8685374 | C16: ZQM: toneladas ÷ (área × edad)
A17: Lucro: días normales entre corte y siembra | B17: 60 | C17: Supuesto: lo que pasa de 60 días es pérdida
A18: Escenario El Niño: déficit final sin cubrir extra (mm) | B18: 117 | C18: Lo que pasó en 2026 (149 contra 32 mm normales)
... A21: Fertilización tardía | B21: 0 | C21: Base de maduración 2026: sin efecto (TARDÍO +8 %, n=3; suelo húmedo +0,9 %, p=0,72)
A23: Curva por número de corte en el mismo lote (para «Menor renovación»)
A24: Corte | B24: Frente a la plantilla | C24: Factor para llevar al lote renovado (promedio de cortes 1-5)
A25: 1 | B25: 0 | C25: 0.88775029
A26: 2 | B26: -0.052675101 | C26: 0.9371128
A27: 3 | B27: -0.077814878 | C27: 0.96265952
A28: 4 | B28: -0.10727627 | C28: 0.99442891
A29: 5 | B29: -0.15089222 | C29: 1.0455095
A30: 6 | B30: -0.16736023 | C30: 1.0661877
A31: 7 | B31: -0.18633946 | C31: 1.0910573
A32: 8 | B32: -0.19996223 | C32: 1.1096355
A33: 9 | B33: -0.20372336 | C33: 1.1148767
A34: 10 | B34: -0.21841878 | C34: 1.1358388
A35: 11 | B35: -0.21426042 | C35: 1.1298276
A36: 12 | B36: -0.19587164 | C36: 1.1039908
A37: 13 | B37: -0.22411236 | C37: 1.1441738
A38: El corte 13 agrupa 13 o más.

Sheet Renovación
A1: Menor área de renovación: suertes del plan 2025 que no se renovaron
A2: 85 suertes no renovadas (93 del plan menos 8 que se renovaron tarde). TCH renovado = TCH × factor de la curva por corte. Pérdida = (TCH renovado − TCH) × ha.
A4: Suerte | B4: Origen | C4: Corte | D4: Área (ha) | E4: TCH (real o motor) | F4: Factor curva | G4: TCH renovado | H4: Toneladas perdidas
A5: 3102-171 | B5: Cosechada 2026 (ene-oct) | C5: 12 | D5: 5.26 | E5: 130.66 | F5: =INDEX('Efectos y supuestos'!$C$25:$C$37,MATCH(MIN(C5,13),'Efectos y supuestos'!$A$25:$A$37,0)) -> 1.1039908 | G5: =E5*F5 -> 144.24744 | H5: =(G5-E5)*D5 -> 71.469909
A6: 3102-190 | B6: Cosechada 2026 (ene-oct) | C6: 11 | D6: 19.25 | E6: 110.80883 | F6: =INDEX('Efectos y supuestos'!$C$25:$C$37,MATCH(MIN(C6,13),'Efectos y supuestos'!$A$25:$A$37,0)) -> 1.1298276 | G6: =E6*F6 -> 125.19488 | H6: =(G6-E6)*D6 -> 276.93142
A7: 3104-120 | B7: Cosechada 2026 (ene-oct) | C7: 10 | D7: 14.42 | E7: 110.08946 | F7: =INDEX('Efectos y supuestos'!$C$25:$C$37,MATCH(MIN(C7,13),'Efectos y supuestos'!$A$25:$A$37,0)) -> 1.1358388 | G7: =E7*F7 -> 125.04388 | H7: =(G7-E7)*D7 -> 215.64277
A8: 3104-123 | B8: Cosechada 2026 (ene-oct) | C8: 11 | D8: 3.72 | E8: 102.76075 | F8: =INDEX('Efectos y supuestos'!$C$25:$C$37,MATCH(MIN(C8,13),'Efectos y supuestos'!$A$25:$A$37,0)) -> 1.1298276 | G8: =E8*F8 -> 116.10194 | H8: =(G8-E8)*D8 -> 49.629208
A9: 3104-131 | B9: Cosechada 2026 (ene-oct) | C9: 9 | D9: 8.94 | E9: 119.3255 | F9: =INDEX('Efectos y supuestos'!$C$25:$C$37,MATCH(MIN(C9,13),'Efectos y supuestos'!$A$25:$A$37,0)) -> 1.1148767 | G9: =E9*F9 -> 133.03323 | H9: =(G9-E9)*D9 -> 122.54704
A10: 3104-220 | B10: Cosechada 2026 (ene-oct) | C10: 7 | D10: 8.41 | E10: 100.99168 | F10: =INDEX('Efectos y supuestos'!$C$25:$C$37,MATCH(MIN(C10,13),'Efectos y supuestos'!$A$25:$A$37,0)) -> 1.0910573 | G10: =E10*F10 -> 110.18771 | H10: =(G10-E10)*D10 -> 77.338627
A11: 3104-351 | B11: Cosechada 2026 (ene-oct) | C11: 10 | D11: 10.18 | E11: 94.231827 | F11: =INDEX('Efectos y supuestos'!$C$25:$C$37,MATCH(MIN(C11,13),'Efectos y supuestos'!$A$25:$A$37,0)) -> 1.1358388 | G11: =E11*F11 -> 107.03217 | H11: =(G11-E11)*D11 -> 130.30746
A12: 3105-430 | B12: Cosechada 2026 (ene-oct) | C12: 9 | D12: 4.74 | E12: 99.816456 | F12: =INDEX('Efectos y supuestos'!$C$25:$C$37,MATCH(MIN(C12,13),'Efectos y supuestos'!$A$25:$A$37,0)) -> 1.1148767 | G12: =E12*F12 -> 111.28304 | H12: =(G12-E12)*D12 -> 54.351623
A13: 3105-601 | B13: Cosechada 2026 (ene-oct) | C13: 14 | D13: 1.93 | E13: 111.2228 | F13: =INDEX('Efectos y supuestos'!$C$25:$C$37,MATCH(MIN(C13,13),'Efectos y supuestos'!$A$25:$A$37,0)) -> 1.1441738 | G13: =E13*F13 -> 127.25821 | H13: =(G13-E13)*D13 -> 30.948344
A14: 3105-650 | B14: Cosechada 2026 (ene-oct) | C14: 8 | D14: 7.28 | E14: 115.03984 | F14: =INDEX('Efectos y supuestos'!$C$25:$C$37,MATCH(MIN(C14,13),'Efectos y supuestos'!$A$25:$A$37,0)) -> 1.1096355 | G14: =E14*F14 -> 127.65228 | H14: =(G14-E14)*D14 -> 91.818613
A15: 3106-040 | B15: Cosechada 2026 (ene-oct) | C15: 11 | D15: 14.22 | E15: 92.924051 | F15: =INDEX('Efectos y supuestos'!$C$25:$C$37,MATCH(MIN(C15,13),'Efectos y supuestos'!$A$25:$A$37,0)) -> 1.1298276 | G15: =E15*F15 -> 104.98816 | H15: =(G15-E15)*D15 -> 171.55163
A16: 3106-100 | B16: Cosechada 2026 (ene-oct) | C16: 8 | D16: 17.11 | E16: 59.74 | F16: =INDEX('Efectos y supuestos'!$C$25:$C$37,MATCH(MIN(C16,13),'Efectos y supuestos'!$A$25:$A$37,0)) -> 1.1096355 | G16: =E16*F16 -> 66.289623 | H16: =(G16-E16)*D16 -> 112.06405
... A74: 3501-623 | B74: Por cosechar 2026 (TCH del motor) | C74: 5 | D74: 5.82 | E74: 78.6 | F74: =INDEX('Efectos y supuestos'!$C$25:$C$37,MATCH(MIN(C74,13),'Efectos y supuestos'!$A$25:$A$37,0)) -> 1.0455095 | G74: =E74*F74 -> 82.17705 | H74: =(G74-E74)*D74 -> 20.818433
A75: Total 2026 | D75: =SUM(D5:D74) -> 635.7 | H75: =SUM(H5:H74) -> 5788.3724
A77: 2027
A78: Ha de las no renovadas que siguen como soca (maestro) | D78: 605.69
A79: Pérdida media por ha de las cosechadas en 2026 (t/ha) | D79: =SUM(H5:H36)/SUM(D5:D36) -> 11.281794
A80: Toneladas 2027 (si no se renuevan) | D80: =D78*D79 -> 6833.27

Sheet Roturación
A1: Oportunidad de la roturación (primera labor)
A2: Pérdida = −efecto × TCH × ha cuando la 1.ª labor fue TARDÍA (>30 días) o sigue pendiente fuera de plazo. NORMAL (16-30 días) no resta.
A4: Suerte | B4: Fecha de corte | C4: Fuente | D4: Oportunidad 1.ª labor | E4: Área (ha) | F4: TCH | G4: Efecto | H4: Toneladas perdidas
A5: 2026: cosechas de 2026 con su roturación (control oficial)
A6: 3102-011 | B6: 45961 | C6: control, por cosechar nov-dic (TCH motor) | D6: IDEAL | E6: 2.62 | F6: 69 | G6: =IF(OR(D6="TARDIO",D6="PENDIENTE (TARDÍO)"),'Efectos y supuestos'!$B$8,0) -> 0 | H6: =-G6*F6*E6 -> 0
A7: 3102-016 | B7: 45847 | C7: control + cosecha | D7: IDEAL | E7: 6.91 | F7: 102.82344 | G7: =IF(OR(D7="TARDIO",D7="PENDIENTE (TARDÍO)"),'Efectos y supuestos'!$B$8,0) -> 0 | H7: =-G7*F7*E7 -> 0
A8: 3102-050 | B8: 45957 | C8: control, por cosechar nov-dic (TCH motor) | D8: IDEAL | E8: 3.18 | F8: 95.3 | G8: =IF(OR(D8="TARDIO",D8="PENDIENTE (TARDÍO)"),'Efectos y supuestos'!$B$8,0) -> 0 | H8: =-G8*F8*E8 -> 0
A9: 3102-060 | B9: 45958 | C9: control, por cosechar nov-dic (TCH motor) | D9: IDEAL | E9: 2.18 | F9: 115.2 | G9: =IF(OR(D9="TARDIO",D9="PENDIENTE (TARDÍO)"),'Efectos y supuestos'!$B$8,0) -> 0 | H9: =-G9*F9*E9 -> 0
A10: 3102-140 | B10: 45812 | C10: control + cosecha | D10: IDEAL | E10: 6.59 | F10: 104.40971 | G10: =IF(OR(D10="TARDIO",D10="PENDIENTE (TARDÍO)"),'Efectos y supuestos'!$B$8,0) -> 0 | H10: =-G10*F10*E10 -> 0
A11: 3102-151 | B11: 45715 | C11: control + cosecha | D11: IDEAL | E11: 10.65 | F11: 155.12019 | G11: =IF(OR(D11="TARDIO",D11="PENDIENTE (TARDÍO)"),'Efectos y supuestos'!$B$8,0) -> 0 | H11: =-G11*F11*E11 -> 0
A12: 3102-181 | B12: 45843 | C12: control + cosecha | D12: IDEAL | E12: 10.57 | F12: 107.79849 | G12: =IF(OR(D12="TARDIO",D12="PENDIENTE (TARDÍO)"),'Efectos y supuestos'!$B$8,0) -> 0 | H12: =-G12*F12*E12 -> 0
A13: 3102-190 | B13: 45850 | C13: control + cosecha | D13: IDEAL | E13: 19.25 | F13: 110.80883 | G13: =IF(OR(D13="TARDIO",D13="PENDIENTE (TARDÍO)"),'Efectos y supuestos'!$B$8,0) -> 0 | H13: =-G13*F13*E13 -> 0
A14: 3102-191 | B14: 45877 | C14: control + cosecha | D14: IDEAL | E14: 4.43 | F14: 104.90971 | G14: =IF(OR(D14="TARDIO",D14="PENDIENTE (TARDÍO)"),'Efectos y supuestos'!$B$8,0) -> 0 | H14: =-G14*F14*E14 -> 0
A15: 3102-280 | B15: 45828 | C15: control + cosecha | D15: IDEAL | E15: 7.97 | F15: 91.974906 | G15: =IF(OR(D15="TARDIO",D15="PENDIENTE (TARDÍO)"),'Efectos y supuestos'!$B$8,0) -> 0 | H15: =-G15*F15*E15 -> 0
A16: 3104-030 | B16: 45765 | C16: control + cosecha | D16: IDEAL | E16: 5.56 | F16: 139.73741 | G16: =IF(OR(D16="TARDIO",D16="PENDIENTE (TARDÍO)"),'Efectos y supuestos'!$B$8,0) -> 0 | H16: =-G16*F16*E16 -> 0
A17: 3104-040 | B17: 45960 | C17: control, por cosechar nov-dic (TCH motor) | D17: IDEAL | E17: 9.14 | F17: 106.7 | G17: =IF(OR(D17="TARDIO",D17="PENDIENTE (TARDÍO)"),'Efectos y supuestos'!$B$8,0) -> 0 | H17: =-G17*F17*E17 -> 0
... A374: 3501-580 | B374: 45824 | C374: control + cosecha | D374: TARDIO | E374: 7.55 | F374: 105.25033 | G374: =IF(OR(D374="TARDIO",D374="PENDIENTE (TARDÍO)"),'Efectos y supuestos'!$B$8,0) -> -0.063 | H374: =-G374*F374*E374 -> 50.06232
A375: Total 2026 (tardías) | E375: =SUMIFS(E6:E374,G6:G374,"<0") -> 284.66 | H375: =SUM(H6:H374) -> 1784.2709
A377: 2027: socas cortadas desde nov-2025 (estado a hoy)
A378: 3102-015 | B378: 46218 | C378: SimpleAgri (−10 días) | D378: IDEAL | E378: 14.02 | F378: 105 | G378: =IF(OR(D378="TARDIO",D378="PENDIENTE (TARDÍO)"),'Efectos y supuestos'!$B$8,0) -> 0 | H378: =-G378*F378*E378 -> 0
A379: 3102-030 | B379: 45976 | C379: control oficial | D379: IDEAL | E379: 21.98 | F379: 108.2 | G379: =IF(OR(D379="TARDIO",D379="PENDIENTE (TARDÍO)"),'Efectos y supuestos'!$B$8,0) -> 0 | H379: =-G379*F379*E379 -> 0
A380: 3102-040 | B380: 46280 | C380: SimpleAgri (−10 días) | D380: IDEAL | E380: 10.72 | F380: 105 | G380: =IF(OR(D380="TARDIO",D380="PENDIENTE (TARDÍO)"),'Efectos y supuestos'!$B$8,0) -> 0 | H380: =-G380*F380*E380 -> 0
A381: 3102-044 | B381: 46006 | C381: control oficial | D381: IDEAL | E381: 3.79 | F381: 120.3 | G381: =IF(OR(D381="TARDIO",D381="PENDIENTE (TARDÍO)"),'Efectos y supuestos'!$B$8,0) -> 0 | H381: =-G381*F381*E381 -> 0
A382: 3102-080 | B382: 45976 | C382: control oficial | D382: IDEAL | E382: 7.03 | F382: 103.4 | G382: =IF(OR(D382="TARDIO",D382="PENDIENTE (TARDÍO)"),'Efectos y supuestos'!$B$8,0) -> 0 | H382: =-G382*F382*E382 -> 0
A383: 3102-081 | B383: 46006 | C383: control oficial | D383: IDEAL | E383: 3.04 | F383: 83.3 | G383: =IF(OR(D383="TARDIO",D383="PENDIENTE (TARDÍO)"),'Efectos y supuestos'!$B$8,0) -> 0 | H383: =-G383*F383*E383 -> 0
A384: 3102-090 | B384: 45976 | C384: control oficial | D384: IDEAL | E384: 12.51 | F384: 107.8 | G384: =IF(OR(D384="TARDIO",D384="PENDIENTE (TARDÍO)"),'Efectos y supuestos'!$B$8,0) -> 0 | H384: =-G384*F384*E384 -> 0
A385: 3102-091 | B385: 46006 | C385: SimpleAgri (−10 días) | D385: IDEAL | E385: 1.42 | F385: 101.7 | G385: =IF(OR(D385="TARDIO",D385="PENDIENTE (TARDÍO)"),'Efectos y supuestos'!$B$8,0) -> 0 | H385: =-G385*F385*E385 -> 0
A386: 3102-100 | B386: 45976 | C386: control oficial | D386: IDEAL | E386: 21.86 | F386: 102.8 | G386: =IF(OR(D386="TARDIO",D386="PENDIENTE (TARDÍO)"),'Efectos y supuestos'!$B$8,0) -> 0 | H386: =-G386*F386*E386 -> 0
A387: 3102-120 | B387: 46006 | C387: control oficial | D387: IDEAL | E387: 10.06 | F387: 117.8 | G387: =IF(OR(D387="TARDIO",D387="PENDIENTE (TARDÍO)"),'Efectos y supuestos'!$B$8,0) -> 0 | H387: =-G387*F387*E387 -> 0
A388: 3102-121 | B388: 46006 | C388: control oficial | D388: IDEAL | E388: 11.96 | F388: 108.1 | G388: =IF(OR(D388="TARDIO",D388="PENDIENTE (TARDÍO)"),'Efectos y supuestos'!$B$8,0) -> 0 | H388: =-G388*F388*E388 -> 0
A389: 3102-151 | B389: 46096 | C389: SimpleAgri (−10 días) | D389: IDEAL | E389: 10.97 | F389: 115 | G389: =IF(OR(D389="TARDIO",D389="PENDIENTE (TARDÍO)"),'Efectos y supuestos'!$B$8,0) -> 0 | H389: =-G389*F389*E389 -> 0
... A844: 3501-510 | B844: 46280 | C844: SimpleAgri (−10 días) | D844: en plazo | E844: 7.82 | F844: 105 | G844: =IF(OR(D844="TARDIO",D844="PENDIENTE (TARDÍO)"),'Efectos y supuestos'!$B$8,0) -> 0 | H844: =-G844*F844*E844 -> 0
A845: Total 2027 (tardías o pendientes fuera de plazo) | E845: =SUMIFS(E378:E844,G378:G844,"<0") -> 906.97 | H845: =SUM(H378:H844) -> 5885.57
A846: TCH 2027: el del motor (si no hay, 105). «PENDIENTE (TARDÍO)» en SimpleAgri puede ser un registro faltante.

Sheet Malezas
A1: Oportunidad del control químico de malezas (primer control del ciclo)
A2: Fecha real de la base de aplicaciones de los contratistas (2025 y ago-oct 2026); donde no hay, SimpleAgri corrida 7 días (desfase medido). Pérdida % = efecto por 30 días × (días − plazo)/30; sin control químico = efecto fijo. Toneladas = −% × TCH × ha.
A4: Suerte | B4: Fecha de corte | C4: Fuente de la fecha | D4: Días al 1.er control (o días ya pasados) | E4: Área (ha) | F4: TCH | G4: Pérdida % | H4: Toneladas perdidas
A5: 2026: socas cosechadas en 2026 (ene-oct)
A6: 3102-010 | B6: 45945 | C6: aplicaciones | D6: 48 | E6: 1.9 | F6: 88.968421 | G6: =IF(C6="sin control",'Efectos y supuestos'!$B$11,'Efectos y supuestos'!$B$9*MAX(0,D6-'Efectos y supuestos'!$B$10)/30) -> 0 | H6: =-G6*F6*E6 -> 0
A7: 3102-012 | B7: 45945 | C7: aplicaciones | D7: 51 | E7: 3.77 | F7: 90 | G7: =IF(C7="sin control",'Efectos y supuestos'!$B$11,'Efectos y supuestos'!$B$9*MAX(0,D7-'Efectos y supuestos'!$B$10)/30) -> 0 | H7: =-G7*F7*E7 -> 0
A8: 3102-015 | B8: 45823 | C8: aplicaciones | D8: 18 | E8: 14.02 | F8: 96.619116 | G8: =IF(C8="sin control",'Efectos y supuestos'!$B$11,'Efectos y supuestos'!$B$9*MAX(0,D8-'Efectos y supuestos'!$B$10)/30) -> 0 | H8: =-G8*F8*E8 -> 0
A9: 3102-016 | B9: 45853 | C9: aplicaciones | D9: 64 | E9: 6.91 | F9: 102.82344 | G9: =IF(C9="sin control",'Efectos y supuestos'!$B$11,'Efectos y supuestos'!$B$9*MAX(0,D9-'Efectos y supuestos'!$B$10)/30) -> 0 | H9: =-G9*F9*E9 -> 0
A10: 3102-017 | B10: 45915 | C10: aplicaciones | D10: 56 | E10: 2.88 | F10: 84.982639 | G10: =IF(C10="sin control",'Efectos y supuestos'!$B$11,'Efectos y supuestos'!$B$9*MAX(0,D10-'Efectos y supuestos'!$B$10)/30) -> 0 | H10: =-G10*F10*E10 -> 0
A11: 3102-020 | B11: 45884 | C11: aplicaciones | D11: -1 | E11: 12.74 | F11: 118.89482 | G11: =IF(C11="sin control",'Efectos y supuestos'!$B$11,'Efectos y supuestos'!$B$9*MAX(0,D11-'Efectos y supuestos'!$B$10)/30) -> 0 | H11: =-G11*F11*E11 -> 0
A12: 3102-040 | B12: 45915 | C12: aplicaciones | D12: 61 | E12: 10.72 | F12: 126.97388 | G12: =IF(C12="sin control",'Efectos y supuestos'!$B$11,'Efectos y supuestos'!$B$9*MAX(0,D12-'Efectos y supuestos'!$B$10)/30) -> 0 | H12: =-G12*F12*E12 -> 0
A13: 3102-110 | B13: 45915 | C13: aplicaciones | D13: 37 | E13: 23.54 | F13: 101.47706 | G13: =IF(C13="sin control",'Efectos y supuestos'!$B$11,'Efectos y supuestos'!$B$9*MAX(0,D13-'Efectos y supuestos'!$B$10)/30) -> 0 | H13: =-G13*F13*E13 -> 0
A14: 3102-140 | B14: 45823 | C14: aplicaciones | D14: 44 | E14: 6.59 | F14: 104.40971 | G14: =IF(C14="sin control",'Efectos y supuestos'!$B$11,'Efectos y supuestos'!$B$9*MAX(0,D14-'Efectos y supuestos'!$B$10)/30) -> 0 | H14: =-G14*F14*E14 -> 0
A15: 3102-151 | B15: 45703 | C15: aplicaciones | D15: 74 | E15: 10.65 | F15: 155.12019 | G15: =IF(C15="sin control",'Efectos y supuestos'!$B$11,'Efectos y supuestos'!$B$9*MAX(0,D15-'Efectos y supuestos'!$B$10)/30) -> 0 | H15: =-G15*F15*E15 -> 0
A16: 3102-160 | B16: 45915 | C16: aplicaciones | D16: 38 | E16: 23.48 | F16: 145.16482 | G16: =IF(C16="sin control",'Efectos y supuestos'!$B$11,'Efectos y supuestos'!$B$9*MAX(0,D16-'Efectos y supuestos'!$B$10)/30) -> 0 | H16: =-G16*F16*E16 -> 0
A17: 3102-171 | B17: 45915 | C17: aplicaciones | D17: 46 | E17: 5.26 | F17: 130.66 | G17: =IF(C17="sin control",'Efectos y supuestos'!$B$11,'Efectos y supuestos'!$B$9*MAX(0,D17-'Efectos y supuestos'!$B$10)/30) -> 0 | H17: =-G17*F17*E17 -> 0
... A60: 3105-430 | B60: 45823 | C60: aplicaciones | D60: 74 | E60: 4.74 | F60: 99.816456 | G60: =IF(C60="sin control",'Efectos y supuestos'!$B$11,'Efectos y supuestos'!$B$9*MAX(0,D60-'Efectos y supuestos'!$B$10)/30) -> 0 | H60: =-G60*F60*E60 -> 0
A61: 3105-600 | B61: 46006 | C61: sin control | E61: 6.19 | F61: 166.26333 | G61: =IF(C61="sin control",'Efectos y supuestos'!$B$11,'Efectos y supuestos'!$B$9*MAX(0,D61-'Efectos y supuestos'!$B$10)/30) -> -0.0524 | H61: =-G61*F61*E61 -> 53.928508
A62: 3105-601 | B62: 45550 | C62: SimpleAgri corregido | D62: 98 | E62: 1.93 | F62: 111.2228 | G62: =IF(C62="sin control",'Efectos y supuestos'!$B$11,'Efectos y supuestos'!$B$9*MAX(0,D62-'Efectos y supuestos'!$B$10)/30) -> -0.0038933333 | H62: =-G62*F62*E62 -> 0.83574293
A63: 3105-610 | B63: 45823 | C63: aplicaciones | D63: 80 | E63: 4.39 | F63: 145.24146 | G63: =IF(C63="sin control",'Efectos y supuestos'!$B$11,'Efectos y supuestos'!$B$9*MAX(0,D63-'Efectos y supuestos'!$B$10)/30) -> 0 | H63: =-G63*F63*E63 -> 0
A64: 3105-612 | B64: 45823 | C64: aplicaciones | D64: 80 | E64: 6.67 | F64: 101.43928 | G64: =IF(C64="sin control",'Efectos y supuestos'!$B$11,'Efectos y supuestos'!$B$9*MAX(0,D64-'Efectos y supuestos'!$B$10)/30) -> 0 | H64: =-G64*F64*E64 -> 0
A65: 3105-613 | B65: 45823 | C65: aplicaciones | D65: 80 | E65: 2.79 | F65: 153.6129 | G65: =IF(C65="sin control",'Efectos y supuestos'!$B$11,'Efectos y supuestos'!$B$9*MAX(0,D65-'Efectos y supuestos'!$B$10)/30) -> 0 | H65: =-G65*F65*E65 -> 0
A66: 3105-640 | B66: 45945 | C66: aplicaciones | D66: 35 | E66: 13.37 | F66: 128.02 | G66: =IF(C66="sin control",'Efectos y supuestos'!$B$11,'Efectos y supuestos'!$B$9*MAX(0,D66-'Efectos y supuestos'!$B$10)/30) -> 0 | H66: =-G66*F66*E66 -> 0
A67: 3105-650 | B67: 45884 | C67: aplicaciones | D67: 68 | E67: 7.28 | F67: 115.03984 | G67: =IF(C67="sin control",'Efectos y supuestos'!$B$11,'Efectos y supuestos'!$B$9*MAX(0,D67-'Efectos y supuestos'!$B$10)/30) -> 0 | H67: =-G67*F67*E67 -> 0
A68: 3105-660 | B68: 45853 | C68: aplicaciones | D68: 62 | E68: 4.07 | F68: 104.76904 | G68: =IF(C68="sin control",'Efectos y supuestos'!$B$11,'Efectos y supuestos'!$B$9*MAX(0,D68-'Efectos y supuestos'!$B$10)/30) -> 0 | H68: =-G68*F68*E68 -> 0
A69: 3106-030 | B69: 45762 | C69: aplicaciones | D69: 59 | E69: 18.81 | F69: 136.60925 | G69: =IF(C69="sin control",'Efectos y supuestos'!$B$11,'Efectos y supuestos'!$B$9*MAX(0,D69-'Efectos y supuestos'!$B$10)/30) -> 0 | H69: =-G69*F69*E69 -> 0
A70: 3106-040 | B70: 45915 | C70: aplicaciones | D70: 79 | E70: 14.22 | F70: 92.924051 | G70: =IF(C70="sin control",'Efectos y supuestos'!$B$11,'Efectos y supuestos'!$B$9*MAX(0,D70-'Efectos y supuestos'!$B$10)/30) -> 0 | H70: =-G70*F70*E70 -> 0
A71: 3106-050 | B71: 45731 | C71: aplicaciones | D71: 59 | E71: 19.21 | F71: 127.2556 | G71: =IF(C71="sin control",'Efectos y supuestos'!$B$11,'Efectos y supuestos'!$B$9*MAX(0,D71-'Efectos y supuestos'!$B$10)/30) -> 0 | H71: =-G71*F71*E71 -> 0
A72: 3106-071 | B72: 45915 | C72: aplicaciones | D72: 130 | E72: 17.67 | F72: 92.53 | G72: =IF(C72="sin control",'Efectos y supuestos'!$B$11,'Efectos y supuestos'!$B$9*MAX(0,D72-'Efectos y supuestos'!$B$10)/30) -> -0.019466667 | H72: =-G72*F72*E72 -> 31.828099
A73: 3106-081 | B73: 45823 | C73: aplicaciones | D73: 104 | E73: 11.68 | F73: 120.93065 | G73: =IF(C73="sin control",'Efectos y supuestos'!$B$11,'Efectos y supuestos'!$B$9*MAX(0,D73-'Efectos y supuestos'!$B$10)/30) -> -0.0068133333 | H73: =-G73*F73*E73 -> 9.6236289
A74: 3106-100 | B74: 45915 | C74: sin control | E74: 17.11 | F74: 59.74 | G74: =IF(C74="sin control",'Efectos y supuestos'!$B$11,'Efectos y supuestos'!$B$9*MAX(0,D74-'Efectos y supuestos'!$B$10)/30) -> -0.0524 | H74: =-G74*F74*E74 -> 53.560733
A75: 3106-110 | B75: 45853 | C75: aplicaciones | D75: 79 | E75: 20.22 | F75: 94.486152 | G75: =IF(C75="sin control",'Efectos y supuestos'!$B$11,'Efectos y supuestos'!$B$9*MAX(0,D75-'Efectos y supuestos'!$B$10)/30) -> 0 | H75: =-G75*F75*E75 -> 0
A76: 3106-130 | B76: 45884 | C76: aplicaciones | D76: 89 | E76: 17.34 | F76: 87.566321 | G76: =IF(C76="sin control",'Efectos y supuestos'!$B$11,'Efectos y supuestos'!$B$9*MAX(0,D76-'Efectos y supuestos'!$B$10)/30) -> 0 | H76: =-G76*F76*E76 -> 0
A77: 3106-150 | B77: 45611 | C77: SimpleAgri corregido | D77: 91 | E77: 17.85 | F77: 114.63754 | G77: =IF(C77="sin control",'Efectos y supuestos'!$B$11,'Efectos y supuestos'!$B$9*MAX(0,D77-'Efectos y supuestos'!$B$10)/30) -> -0.00048666667 | H77: =-G77*F77*E77 -> 0.99585627
A78: 3106-160 | B78: 45915 | C78: aplicaciones | D78: 59 | E78: 6.39 | F78: 107.0892 | G78: =IF(C78="sin control",'Efectos y supuestos'!$B$11,'Efectos y supuestos'!$B$9*MAX(0,D78-'Efectos y supuestos'!$B$10)/30) -> 0 | H78: =-G78*F78*E78 -> 0
A79: 3106-171 | B79: 45884 | C79: aplicaciones | D79: 55 | E79: 11.1 | F79: 94.943243 | G79: =IF(C79="sin control",'Efectos y supuestos'!$B$11,'Efectos y supuestos'!$B$9*MAX(0,D79-'Efectos y supuestos'!$B$10)/30) -> 0 | H79: =-G79*F79*E79 -> 0
A80: 3106-180 | B80: 45884 | C80: aplicaciones | D80: 75 | E80: 17.56 | F80: 97.019362 | G80: =IF(C80="sin control",'Efectos y supuestos'!$B$11,'Efectos y supuestos'!$B$9*MAX(0,D80-'Efectos y supuestos'!$B$10)/30) -> 0 | H80: =-G80*F80*E80 -> 0
A81: 3106-190 | B81: 45915 | C81: aplicaciones | D81: 112 | E81: 17.14 | F81: 108.18 | G81: =IF(C81="sin control",'Efectos y supuestos'!$B$11,'Efectos y supuestos'!$B$9*MAX(0,D81-'Efectos y supuestos'!$B$10)/30) -> -0.010706667 | H81: =-G81*F81*E81 -> 19.852357
A82: 3106-210 | B82: 45884 | C82: aplicaciones | D82: 102 | E82: 5.24 | F82: 101.45611 | G82: =IF(C82="sin control",'Efectos y supuestos'!$B$11,'Efectos y supuestos'!$B$9*MAX(0,D82-'Efectos y supuestos'!$B$10)/30) -> -0.00584 | H82: =-G82*F82*E82 -> 3.1047192
A83: 3106-211 | B83: 45915 | C83: SimpleAgri corregido | D83: 143 | E83: 5.23 | F83: 89.46 | G83: =IF(C83="sin control",'Efectos y supuestos'!$B$11,'Efectos y supuestos'!$B$9*MAX(0,D83-'Efectos y supuestos'!$B$10)/30) -> -0.025793333 | H83: =-G83*F83*E83 -> 12.068076
...

Sheet Riego y lluvia
A1: Falta de riego y precipitaciones
A2: Falta de riego = déficit de agua (evaporación − lluvia − riego) que quedó sin cubrir, frente a lo normal 2022-25. Precipitaciones = lluvia de los primeros 3 meses del ciclo.
A4: 2026 (cosechas ene-sep) | B4: 2026 (mm) | C4: Normal 2022-25 (mm) | D4: Diferencia (mm) | E4: Efecto por 100 mm | F4: Aporte al TCH
A5: Déficit sin cubrir meses 0-4 | B5: -13.279181 | C5: 35.152935 | D5: =B5-C5 -> -48.432116 | E5: ='Efectos y supuestos'!$B$12 -> 0.0070166177 | F5: =E5*D5/100 -> -0.0033982964
A6: Déficit sin cubrir meses 4-8 | B6: -99.868944 | C6: -43.837057 | D6: =B6-C6 -> -56.031887 | E6: ='Efectos y supuestos'!$B$13 -> -0.0045347778 | F6: =E6*D6/100 -> 0.0025409216
A7: Déficit sin cubrir mes 8 a cosecha | B7: 149.36161 | C7: 32.38138 | D7: =B7-C7 -> 116.98023 | E7: ='Efectos y supuestos'!$B$14 -> -0.012535365 | F7: =E7*D7/100 -> -0.014663898
A8: Producción ene-sep 2026 (t) y ha | B8: 306958.67 | C8: 2786.39
A9: Falta de riego 2026: toneladas (columna C = ha con déficit final mayor a lo normal) | C9: 2117.66 | F9: =-SUM(F5:F7)*B8 -> 4764.3892
A11: Lluvia del arranque (meses 0-3), cosechas ene-sep | B11: 376.15935 | C11: 348.23606 | D11: =B11-C11 -> 27.923292 | E11: ='Efectos y supuestos'!$B$15 -> -0.012079619 | F11: =E11*D11/100 -> -0.0033730272
A12: Precipitaciones 2026: toneladas (columna C = ha con lluvia de arranque mayor a lo normal) | C12: 1874.52 | F12: =-F11*B8 -> 1035.3799
A14: 2027 (lo que la caña ya vivió) | B14: Cohorte (mm) | C14: Normal (mm) | D14: Diferencia (mm) | E14: Efecto por 100 mm | F14: Ha de la etapa
A15: Déficit sin cubrir meses 0-4 | B15: 56.477709 | C15: 35.796348 | D15: =B15-C15 -> 20.681361 | E15: ='Efectos y supuestos'!$B$12 -> 0.0070166177 | F15: 2615.89
A16: Déficit sin cubrir meses 4-8 | B16: -0.0099253557 | C16: -72.443277 | D16: =B16-C16 -> 72.433352 | E16: ='Efectos y supuestos'!$B$13 -> -0.0045347778 | F16: 1734.36
A17: Lluvia del arranque (meses 0-3) | B17: 301.41316 | C17: 314.46756 | D17: =B17-C17 -> -13.054403 | E17: ='Efectos y supuestos'!$B$15 -> -0.012079619 | F17: 2977.41
A19: Toneladas (− = a favor) = −efecto × diferencia/100 × ha × TCH esperado 2027
A20: Riego medido hasta hoy 2027 | F20: =-(E15*D15/100*F15+E16*D16/100*F16)*'Efectos y supuestos'!$B$19 -> 196.92659
A21: Escenario El Niño 2027 (final del ciclo como 2026) | C21: ='Efectos y supuestos'!$B$7 -> 5393 | F21: =-'Efectos y supuestos'!$B$14*'Efectos y supuestos'!$B$18/100*'Efectos y supuestos'!$B$7*'Efectos y supuestos'!$B$19 -> 8194.3217
A22: Precipitaciones 2027 (arranque; columna C = ha con arranque más seco que lo normal, a favor) | C22: 1303.71 | F22: =-E17*D17/100*F17*'Efectos y supuestos'!$B$19 -> -486.41689
A23: En la diapositiva, la falta de riego 2027 es el escenario El Niño; lo medido hasta hoy (fila 20) casi no resta.

Sheet Lucro cesante
A1: Lucro cesante: días que el lote quedó cortado y sin sembrar
A2: Toneladas = ha × (días − días normales) / 30,44 × TCHM. Con todos los días, columna aparte.
A4: Suerte | B4: Área (ha) | C4: Corte anterior | D4: Siembra (o hoy) | E4: Días sin caña | F4: Días por encima de lo normal | G4: Toneladas perdidas | H4: Toneladas con todos los días
A5: 2026: renovaciones sembradas en 2026
A6: 3104-070 | B6: 14.29 | C6: 45672 | D6: 46181 | E6: =D6-C6 -> 509 | F6: =MAX(0,E6-'Efectos y supuestos'!$B$17) -> 449 | G6: =B6*F6/30.44*'Efectos y supuestos'!$B$16 -> 2080.112 | H6: =B6*E6/30.44*'Efectos y supuestos'!$B$16 -> 2358.0779
A7: 3113-110 | B7: 15.24 | C7: 45853 | D7: 46262 | E7: =D7-C7 -> 409 | F7: =MAX(0,E7-'Efectos y supuestos'!$B$17) -> 349 | G7: =B7*F7/30.44*'Efectos y supuestos'!$B$16 -> 1724.3227 | H7: =B7*E7/30.44*'Efectos y supuestos'!$B$16 -> 2020.7678
A8: 3109-310 | B8: 15.77 | C8: 45853 | D8: 46234 | E8: =D8-C8 -> 381 | F8: =MAX(0,E8-'Efectos y supuestos'!$B$17) -> 321 | G8: =B8*F8/30.44*'Efectos y supuestos'!$B$16 -> 1641.1371 | H8: =B8*E8/30.44*'Efectos y supuestos'!$B$16 -> 1947.8917
A9: 3501-230 | B9: 8.5 | C9: 45731 | D9: 46078 | E9: =D9-C9 -> 347 | F9: =MAX(0,E9-'Efectos y supuestos'!$B$17) -> 287 | G9: =B9*F9/30.44*'Efectos y supuestos'!$B$16 -> 790.87704 | H9: =B9*E9/30.44*'Efectos y supuestos'!$B$16 -> 956.21718
A10: 3501-540 | B10: 10.11 | C10: 45823 | D10: 46128 | E10: =D10-C10 -> 305 | F10: =MAX(0,E10-'Efectos y supuestos'!$B$17) -> 245 | G10: =B10*F10/30.44*'Efectos y supuestos'!$B$16 -> 803.01819 | H10: =B10*E10/30.44*'Efectos y supuestos'!$B$16 -> 999.6757
A11: 3113-070 | B11: 15.17 | C11: 45909 | D11: 46203 | E11: =D11-C11 -> 294 | F11: =MAX(0,E11-'Efectos y supuestos'!$B$17) -> 234 | G11: =B11*F11/30.44*'Efectos y supuestos'!$B$16 -> 1150.8258 | H11: =B11*E11/30.44*'Efectos y supuestos'!$B$16 -> 1445.9093
A12: 3122-050 | B12: 16.83 | C12: 45896 | D12: 46123 | E12: =D12-C12 -> 227 | F12: =MAX(0,E12-'Efectos y supuestos'!$B$17) -> 167 | G12: =B12*F12/30.44*'Efectos y supuestos'!$B$16 -> 911.18955 | H12: =B12*E12/30.44*'Efectos y supuestos'!$B$16 -> 1238.563
A13: 3109-061 | B13: 11.43 | C13: 46068 | D13: 46268 | E13: =D13-C13 -> 200 | F13: =MAX(0,E13-'Efectos y supuestos'!$B$17) -> 140 | G13: =B13*F13/30.44*'Efectos y supuestos'!$B$16 -> 518.77903 | H13: =B13*E13/30.44*'Efectos y supuestos'!$B$16 -> 741.11289
A14: 3122-150 | B14: 13.49 | C14: 45918 | D14: 46107 | E14: =D14-C14 -> 189 | F14: =MAX(0,E14-'Efectos y supuestos'!$B$17) -> 129 | G14: =B14*F14/30.44*'Efectos y supuestos'!$B$16 -> 564.16976 | H14: =B14*E14/30.44*'Efectos y supuestos'!$B$16 -> 826.5743
A15: 3104-020 | B15: 10.42 | C15: 46006 | D15: 46192 | E15: =D15-C15 -> 186 | F15: =MAX(0,E15-'Efectos y supuestos'!$B$17) -> 126 | G15: =B15*F15/30.44*'Efectos y supuestos'!$B$16 -> 425.64389 | H15: =B15*E15/30.44*'Efectos y supuestos'!$B$16 -> 628.33146
A16: 3110-110 | B16: 14.92 | C16: 45916 | D16: 46095 | E16: =D16-C16 -> 179 | F16: =MAX(0,E16-'Efectos y supuestos'!$B$17) -> 119 | G16: =B16*F16/30.44*'Efectos y supuestos'!$B$16 -> 575.60416 | H16: =B16*E16/30.44*'Efectos y supuestos'!$B$16 -> 865.82475
A17: 3110-031 | B17: 5.91 | C17: 45912 | D17: 46090 | E17: =D17-C17 -> 178 | F17: =MAX(0,E17-'Efectos y supuestos'!$B$17) -> 118 | G17: =B17*F17/30.44*'Efectos y supuestos'!$B$16 -> 226.08806 | H17: =B17*E17/30.44*'Efectos y supuestos'!$B$16 -> 341.04809
... A40: 3501-431 | B40: 3.17 | C40: 46267 | D40: 46288 | E40: =D40-C40 -> 21 | F40: =MAX(0,E40-'Efectos y supuestos'!$B$17) -> 0 | G40: =B40*F40/30.44*'Efectos y supuestos'!$B$16 -> 0 | H40: =B40*E40/30.44*'Efectos y supuestos'!$B$16 -> 21.581752
A41: Total 2026 | B41: =SUM(B6:B40) -> 332.23 | G41: =SUM(G6:G40) -> 13663.032 | H41: =SUM(H6:H40) -> 19856.34
A43: 2027: cortadas y todavía sin sembrar (días hasta 21/10/2026)
A44: 3110-050 | B44: 8.33 | C44: 46006 | D44: 46316 | E44: =D44-C44 -> 310 | F44: =MAX(0,E44-'Efectos y supuestos'!$B$17) -> 250 | G44: =B44*F44/30.44*'Efectos y supuestos'!$B$16 -> 675.13893 | H44: =B44*E44/30.44*'Efectos y supuestos'!$B$16 -> 837.17228
A45: 3111-200 | B45: 12.44 | C45: 46282 | D45: 46316 | E45: =D45-C45 -> 34 | F45: =MAX(0,E45-'Efectos y supuestos'!$B$17) -> 0 | G45: =B45*F45/30.44*'Efectos y supuestos'!$B$16 -> 0 | H45: =B45*E45/30.44*'Efectos y supuestos'!$B$16 -> 137.1221
A46: Total 2027 (hasta hoy) | B46: =SUM(B44:B45) -> 20.77 | G46: =SUM(G44:G45) -> 675.13893 | H46: =SUM(H44:H45) -> 974.29437
A47: Falta el plan de renovación 2026-27: las renovaciones que se corten de aquí en adelante sumarán lucro en 2027.

Sheet Corte a siembra
A1: Oportunidad corte a siembra: efecto en el TCH de la plantilla
A2: 419 plantillas cosechadas 2019-2026 con siembra (maestro) y corte anterior conocidos; TCH con efectos de año, mes, edad y variedad.
A4: Días entre corte y siembra | B4: Plantillas | C4: TCH medio | D4: Frente a ≤60 días
A5: ≤60 | B5: 71 | C5: 127.47947 | D5: base
A6: 61-120 | B6: 153 | C6: 138.05215 | D6: +4,3 % (p=0,07)
A7: 121-180 | B7: 92 | C7: 138.42161 | D7: +5,2 % (p=0,05)
A8: >180 | B8: 103 | C8: 130.74442 | D8: +2,0 % (p=0,44)
A10: Lineal: −0,8 % por cada 100 días (p=0,22, no significativo). En la diapositiva = 0 t.
A12: Plantillas de 2026 (cosechadas) | B12: Área (ha) | C12: Días sin caña | D12: TCH
A13: 3111-520 | B13: 14.47 | C13: 547 | D13: 128.12
A14: 3111-140 | B14: 10.87 | C14: 372 | D14: 126.34039
A15: 3109-271 | B15: 7.84 | C15: 296 | D15: 147.68367
A16: 3109-270 | B16: 7.8 | C16: 295 | D16: 133.33333
A17: 3111-141 | B17: 10.22 | C17: 259 | D17: 123.96
A18: 3122-130 | B18: 8.5 | C18: 245 | D18: 142.54
A19: 3122-130 | B19: 8.5 | C19: 245 | D19: 142.53882
A20: 3106-060 | B20: 15.45 | C20: 227 | D20: 120.41748
A21: 3106-060 | B21: 15.55 | C21: 227 | D21: 120.42
A22: 3113-190 | B22: 5.75 | C22: 221 | D22: 130.8487
A23: 3104-150 | B23: 10.33 | C23: 220 | D23: 144.01936
A24: 3501-150 | B24: 14.26 | C24: 215 | D24: 109.95
... A50: 3121-240 | B50: 5.08 | C50: 43 | D50: 137.95
A51: Plantillas 2026 con más de 60 días entre corte y siembra (ha) | B51: =SUMIFS(B13:B50,C13:C50,">60") -> 302.75
A53: Plantillas sembradas desde oct-2025 (cosecha 2027) | B53: Área (ha) | C53: Días sin caña | D53: Siembra
A54: 3104-070 | B54: 14.29 | C54: 509 | D54: 46181
A55: 3113-110 | B55: 15.24 | C55: 409 | D55: 46262
A56: 3109-310 | B56: 15.77 | C56: 381 | D56: 46234
A57: 3501-230 | B57: 8.5 | C57: 347 | D57: 46078
A58: 3501-540 | B58: 10.11 | C58: 305 | D58: 46128
A59: 3113-070 | B59: 15.17 | C59: 294 | D59: 46203
A60: 3104-171 | B60: 14.18 | C60: 260 | D60: 45991
A61: 3105-310 | B61: 11 | C61: 230 | D61: 45961
A62: 3122-050 | B62: 16.83 | C62: 227 | D62: 46123
A63: 3501-150 | B63: 14.26 | C63: 215 | D63: 45946
A64: 3501-130 | B64: 8.54 | C64: 206 | D64: 45937
A65: 3109-061 | B65: 11.43 | C65: 200 | D65: 46268
... A108: 3501-431 | B108: 3.17 | C108: 21 | D108: 46288
A109: Plantillas 2027 con más de 60 días entre corte y siembra (ha) | B109: =SUMIFS(B54:B108,C54:C108,">60") -> 453.39

Sheet Fertilización
A1: Oportunidad y calidad de la fertilización (base de validación de maduración Riopaila 2026)
A2: 227 cortes de ene-ago 2026 cruzados con el ZQM. TCH frente al promedio 2020-25 de la misma suerte. Ninguna calificación bajó el TCH: efecto = 0.
A4: Suerte | B4: Mes | C4: Área (ha) | D4: Oportunidad fertilización | E4: Suelo al fertilizar | F4: Calificación (1-5) | G4: Oportunidad roturación | H4: Suelo al roturar | I4: TCH | J4: Frente a su promedio 2020-25
A5: 3102-015 | B5: 7 | C5: 14.02 | D5: IDEAL-NORMAL | E5: HUMEDO | F5: 3 | G5: IDEAL-NORMAL | H5: FRIABLE | I5: 96.619116 | J5: -0.012610619
A6: 3102-016 | B6: 7 | C6: 6.91 | D6: IDEAL-NORMAL | E6: FRIABLE | F6: 1 | G6: IDEAL-NORMAL | H6: FRIABLE | I6: 102.82344 | J6: -0.011561647
A7: 3102-020 | B7: 8 | C7: 12.74 | D7: IDEAL-NORMAL | E7: HUMEDO | F7: 3 | G7: IDEAL-NORMAL | H7: HUMEDO | I7: 118.89482 | J7: 0.14718128
A8: 3102-140 | B8: 6 | C8: 6.59 | D8: IDEAL-NORMAL | E8: FRIABLE | F8: 1 | G8: IDEAL-NORMAL | H8: HUMEDO | I8: 104.40971 | J8: -0.18252834
A9: 3102-151 | B9: 3 | C9: 10.65 | D9: IDEAL-NORMAL | E9: FRIABLE | F9: 1 | G9: IDEAL-NORMAL | H9: HUMEDO | I9: 155.12019 | J9: 0.22263389
A10: 3102-181 | B10: 7 | C10: 10.57 | D10: IDEAL-NORMAL | E10: FRIABLE | F10: 1 | G10: IDEAL-NORMAL | H10: FRIABLE | I10: 107.79849 | J10: -0.14144045
A11: 3102-190 | B11: 7 | C11: 19.25 | D11: IDEAL-NORMAL | E11: FRIABLE | F11: 1 | G11: IDEAL-NORMAL | H11: FRIABLE | I11: 110.80883 | J11: -0.076794067
A12: 3102-191 | B12: 8 | C12: 4.43 | D12: IDEAL-NORMAL | E12: HUMEDO | F12: 3 | G12: IDEAL-NORMAL | H12: HUMEDO | I12: 104.90971 | J12: -0.049508886
A13: 3102-280 | B13: 7 | C13: 7.97 | D13: IDEAL-NORMAL | E13: HUMEDO | F13: 3 | G13: IDEAL-NORMAL | H13: FRIABLE | I13: 91.974906 | J13: -0.20933899
A14: 3104-021 | B14: 8 | C14: 6.68 | D14: IDEAL-NORMAL | E14: HUMEDO | F14: 3 | G14: IDEAL-NORMAL | H14: HUMEDO | I14: 139.26796 | J14: 0.63441305
A15: 3104-030 | B15: 4 | C15: 5.56 | D15: IDEAL-NORMAL | E15: HUMEDO | F15: 3 | G15: IDEAL-NORMAL | H15: HUMEDO | I15: 139.73741 | J15: 0.3435575
A16: 3104-041 | B16: 3 | C16: 10.36 | D16: IDEAL-NORMAL | E16: FRIABLE | F16: 1 | G16: IDEAL-NORMAL | H16: FRIABLE | I16: 113.48552 | J16: 0.01484298
... A231: 3501-651 | B231: 6 | C231: 5.03 | D231: IDEAL-NORMAL | E231: HUMEDO | F231: 3 | G231: IDEAL-NORMAL | H231: HUMEDO | I231: 90.83499 | J231: -0.2504229
A232: Fertilización TARDÍA 2026 (ha) | C232: =SUMIFS(C5:C231,D5:D231,"TARDIO") -> 22.79
A234: Efectos (modelo con mes, edad, corte y tipo de cosecha): oportunidad TARDÍO +8,2 % (n=3); suelo húmedo +0,9 % (p=0,72); calificación 1-5 +0,6 % por punto (p=0,61). Roturación TARDÍO −6,2 % (n=6), confirma el control oficial.
A235: 2027 (SimpleAgri, socas cortadas desde nov-2025): primera fertilización después de 120 días | C235: 440.52

Sheet Cómo se hizo
A1: Fuentes
A2: Cosechas: ZQM histórico 2011-2025, G&P Suertes_26 (hoja ZQM101, ene-sep 2026) y app de Cosecha (octubre). Maestro de suertes de Riopaila. Estimados del motor (corrida 16-oct-2026).
A3: Renovación: «Areas no renovadas.xlsx» (plan 2025: 124 suertes; 93 marcadas NO, de las que 8 se renovaron tarde).
A4: Roturación: «CONTROL DE ROTURACION. est 2025 con formatos.xlsm» (cortes oct-2023 a ene-2026, criterio de Riopaila: IDEAL ≤15 días, NORMAL 16-30, TARDÍO >30) y SimpleAgri (planillas de roturación 540-544) para los cortes posteriores, corridas 10 días porque la planilla se confirma después de la labor.
A5: Malezas: fecha real de aplicación de las bases de aplicaciones de los contratistas («LABOR APLICACIONES 31-12-2025» y «BASE DE DATOS APLICACIONES 2026», 14-ago a 10-oct-2026); donde no hay (feb-ago 2026 o antes de 2025), SimpleAgri corrida 7 días, el desfase medido entre la aplicación y la confirmación de la planilla. Fertilización: base de validación de maduración Riopaila 2026 y SimpleAgri.
A6: Riego: «CONSOLIDADO DE RIEGOS 2026-.xlsx» (área regada y lámina por riego). Clima: EMA La Paila y Bugalagrande (repositorio de precipitación de Riopaila) completadas con el Meteoportal de Cenicaña.
A7: Lucro cesante y corte a siembra: fechas de siembra del maestro y fecha del corte anterior (ZQM, archivo de áreas no renovadas).
A9: Método
A10: Cada efecto se midió con cosechas reales de Riopaila (2024-2026 para las labores), comparando cada suerte con su propio promedio 2020-25 y descontando año, mes, edad y número de corte. Las toneladas de 2026 y 2027 aplican ese efecto a las suertes de cada año (hojas por factor).
A11: 2026 = cosechas del año (ene-oct reales y nov-dic con el TCH del motor donde aplica). 2027 = caña que se está levantando, con el estado de las labores a hoy: lo pendiente cuenta con los días que ya pasaron, así que es un mínimo.
A12: Programas: carpeta «01 Estimados y TCH/Caida TCH 2026 - programas» (no_renovadas_2026, roturacion, labores_sa, labores_perdidas, riego_2026, riego_2027, siembra_lucro, impacto_excel).
